Workbook

Sheet Tổng quan
A1: QUICKASSIST — PHÂN TÍCH & KẾ HOẠCH NHÓM 4 NGƯỜI (BẢN ẨN DANH)
A3: Mục tiêu | B3: Xây extension ghi chú nhanh, quản lý note và tra cứu ngữ nghĩa; kiến trúc mở để dùng dịch vụ hoặc tự triển khai.
A4: Mốc kế hoạch | B4: 8 tuần — khóa phạm vi P0 trước; P1 chỉ làm sau khi P0 đạt Definition of Done.
A5: MVP đề xuất | B5: Tài khoản/auth + ghi chú nhanh + thư viện/CRUD/cache + RAG cơ bản + bảo mật/kiểm thử.
A6: Ngoài MVP | B6: Skim trang là P1; tóm tắt phải bổ sung kịch bản; lịch trình cá nhân/consent là P2.
A7: Nguồn phân tích | B7: Nhóm 1 - Báo cáo ý tưởng đề tài.docx; Kịch bản chức năng QuickAssist_1.xlsx
A9: Nhận định chính
A10: 1. | B10: Kiến trúc gồm Extension/UI ↔ Server ↔ AI Provider, với PostgreSQL + pgvector và IndexedDB làm cache/offline.
A11: 2. | B11: Kịch bản đã mô tả tốt 5 luồng: ghi chú nhanh, skim trang, duyệt note, RAG và CRUD; nhưng account/auth mới ở mức ý tưởng.
A12: 3. | B12: Mấu chốt dữ liệu là ownership theo user, metadata/category, UUID note/chunk, quota và đồng bộ local–server.
A13: 4. | B13: Hai contract phải chốt trước code: endpoint ghi chú và quy tắc response/error/idempotency.
A14: 5. | B14: Tóm tắt nội dung và lịch trình cá nhân chưa đủ đặc tả; không nên cam kết trong MVP trước khi làm G01/G02.
A15: 6. | B15: RAG nên có benchmark chất lượng/độ trễ; luôn có timeout/fallback để demo không phụ thuộc tuyệt đối vào provider.
A18: Thành viên | B18: Vai trò chính | C18: Trách nhiệm
A19: Người A | B19: Tech Lead / Browser Extension | C19: Kiến trúc tổng thể, Manifest V3, TypeScript, IndexedDB, tích hợp UI–API
A20: Người B | B20: Backend Lead | C20: API Python, xác thực, PostgreSQL/pgvector, quota, đồng bộ dữ liệu
A21: Người C | B21: AI/RAG Lead | C21: Chunking, embedding, hybrid search, reranking, đánh giá chất lượng AI
A22: Người D | B22: UI/UX & QA Lead | C22: Luồng giao diện, trạng thái lỗi, kiểm thử, tài liệu và demo
A25: Definition of Done chung
A26: ✓ | B26: Có acceptance criteria và test tương ứng; code được thành viên phối hợp review.
A27: ✓ | B27: Build/lint/unit/integration liên quan đều pass; không còn lỗi P0/P1 mở.
A28: ✓ | B28: Không log token/nội dung nhạy cảm; kiểm tra ownership và validation ở server.
A29: ✓ | B29: API/schema/tài liệu được cập nhật cùng thay đổi; demo được trên dữ liệu mẫu.

Sheet Ma trận chức năng
A1: MA TRẬN PHẠM VI & MỨC ĐỘ ĐẶC TẢ
A3: Chức năng | B3: Nguồn | C3: Mức đặc tả | D3: Ưu tiên | E3: Nhận xét / quyết định
A4: Tài khoản cá nhân | B4: Word | C4: Một phần | D4: P0 | E4: Cần chốt auth/token, quota, profile và quyền riêng tư
A5: Ghi chú nhanh | B5: Word + Excel | C5: Chi tiết | D5: P0 | E5: Luồng selection → undo 5s → lưu → AI xử lý → local state
A6: Tìm văn bản nổi bật trên trang | B6: Excel | C6: Chi tiết | D6: P1 | E6: Readability + session tạm + hybrid search + chọn đoạn để lưu
A7: Duyệt note/cache | B7: Excel | C7: Chi tiết | D7: P0 | E7: Cache-first IndexedDB, sync server và hiển thị thư viện
A8: Tra cứu note RAG-like | B8: Word + Excel | C8: Chi tiết | D8: P0 | E8: Filter theo user/category; BM25 + vector + rerank
A9: Note CRUD | B9: Excel | C9: Chi tiết | D9: P0 | E9: Sửa/xoá/bulk delete và cập nhật local tương ứng
A10: Tóm tắt nội dung | B10: Word | C10: Thiếu kịch bản | D10: P1 | E10: Phải bổ sung scenario, API, UI, quota, lưu trữ và acceptance
A11: Trích xuất lịch trình cá nhân | B11: Word | C11: Ý tưởng sơ bộ | D11: P2 | E11: Rủi ro privacy/consent; nên để sau MVP
A12: Tự triển khai/local AI | B12: Word | C12: Định hướng | D12: P1 | E12: Cần adapter và hướng dẫn cấu hình, không khóa vào một provider

Sheet Backlog phân công
A1: BACKLOG PHÂN CÔNG CHI TIẾT — BẢN ẨN DANH
A3: ID | B3: Giai đoạn | C3: Hạng mục | D3: Task | E3: Người phụ trách | F3: Phối hợp | G3: Tuần BĐ | H3: Tuần KT | I3: Giờ | J3: Ưu tiên | K3: Phụ thuộc | L3: Deliverable | M3: Tiêu chí nghiệm thu | N3: Trạng thái | O3: % hoàn thành
A4: P01 | B4: Khởi động | C4: Kiến trúc | D4: Chốt kiến trúc, module, luồng dữ liệu và ADR | E4: Người A | F4: Người B | G4: 1 | H4: 1 | I4: 6 | J4: P0 | L4: Sơ đồ kiến trúc + ADR | M4: Nhóm duyệt; thể hiện extension/server/AI/DB và ranh giới dữ liệu | N4: Chưa bắt đầu | O4: 0
A5: P02 | B5: Khởi động | C5: API & dữ liệu | D5: Chuẩn hoá endpoint và data contract; xử lý xung đột /notes/quick, /notes, /notes/ragged | E5: Người B | F5: Người A | G5: 1 | H5: 1 | I5: 8 | J5: P0 | K5: P01 | L5: OpenAPI draft + schema | M5: Không còn endpoint mâu thuẫn; có request/response/error mẫu | N5: Chưa bắt đầu | O5: 0
A6: P03 | B6: Khởi động | C6: AI | D6: Spike lựa chọn AI Provider: Dify hay service riêng; đo khả năng chunk/embed/rerank | E6: Người C | F6: Người B | G6: 1 | H6: 1 | I6: 8 | J6: P0 | K6: P01 | L6: Báo cáo spike + quyết định | M6: Có tiêu chí latency, chi phí/quota, khả năng chạy local | N6: Chưa bắt đầu | O6: 0
A7: P04 | B7: Khởi động | C7: UX | D7: Vẽ user flow và wireframe cho 5 chức năng trong kịch bản | E7: Người D | F7: Người A | G7: 1 | H7: 1 | I7: 8 | J7: P0 | K7: P01 | L7: Wireframe + user flow | M7: Bao phủ happy path, loading, empty, error, undo | N7: Chưa bắt đầu | O7: 0
A8: P05 | B8: Nền tảng | C8: Extension | D8: Khởi tạo TypeScript + Manifest V3, build/lint/test và cấu trúc module | E8: Người A | F8: Người D | G8: 1 | H8: 2 | I8: 8 | J8: P0 | K8: P01 | L8: Extension skeleton | M8: Cài được ở developer mode; build và lint pass | N8: Chưa bắt đầu | O8: 0
A9: P06 | B9: Nền tảng | C9: Backend | D9: Khởi tạo Python API, cấu hình môi trường, health check và test framework | E9: Người B | F9: Người C | G9: 1 | H9: 2 | I9: 8 | J9: P0 | K9: P01 | L9: Backend skeleton | M9: Health check chạy; test smoke pass; cấu hình tách dev/test | N9: Chưa bắt đầu | O9: 0
A10: P07 | B10: Nền tảng | C10: AI | D10: Khởi tạo AI service/adapter cho local provider và mock provider | E10: Người C | F10: Người B | G10: 1 | H10: 2 | I10: 8 | J10: P0 | K10: P03,P06 | L10: AI adapter skeleton | M10: Đổi provider qua config; có mock deterministic cho test | N10: Chưa bắt đầu | O10: 0
A11: P08 | B11: Nền tảng | C11: QA | D11: Lập test strategy, traceability matrix từ kịch bản và Definition of Done | E11: Người D | F11: Người A | G11: 1 | H11: 2 | I11: 6 | J11: P0 | K11: P04 | L11: Test plan + RTM | M11: Mỗi nhánh chính có test case và người chịu trách nhiệm | N11: Chưa bắt đầu | O11: 0
A12: A01 | B12: Nền tảng | C12: Tài khoản | D12: Thiết kế schema user/note/chunk/category/quota và migration | E12: Người B | F12: Người C | G12: 2 | H12: 2 | I12: 8 | J12: P0 | K12: P02,P06 | L12: Migration + ERD | M12: Có UUID, ownership, timestamp, index và ràng buộc dữ liệu | N12: Chưa bắt đầu | O12: 0
A13: A02 | B13: Nền tảng | C13: Tài khoản | D13: Xây dựng đăng ký/đăng nhập, hash mật khẩu và token/session | E13: Người B | F13: Người A | G13: 2 | H13: 3 | I13: 10 | J13: P0 | K13: A01 | L13: Auth API | M13: Không lưu mật khẩu thô; test success/failure/expiry pass | N13: Chưa bắt đầu | O13: 0
A14: A03 | B14: Nền tảng | C14: Tài khoản | D14: Tích hợp đăng nhập và lưu token an toàn trong extension | E14: Người A | F14: Người B | G14: 2 | H14: 3 | I14: 8 | J14: P0 | K14: A02,P05 | L14: Auth UI + client | M14: Login/logout hoạt động; không log token; xử lý token hết hạn | N14: Chưa bắt đầu | O14: 0
A15: A04 | B15: Nền tảng | C15: Quota | D15: Xây dựng quota middleware và nhật ký tiêu hao AI | E15: Người B | F15: Người C | G15: 3 | H15: 3 | I15: 8 | J15: P0 | K15: A01,A02 | L15: Quota service | M15: Chặn đúng khi hết quota; cập nhật nguyên tử; có audit | N15: Chưa bắt đầu | O15: 0
A16: A05 | B16: Nền tảng | C16: UI | D16: Xây design system và app shell: loading/empty/error/toast/modal | E16: Người D | F16: Người A | G16: 2 | H16: 3 | I16: 8 | J16: P0 | K16: P04,P05 | L16: UI component set | M16: Các màn hình dùng chung component; keyboard usable | N16: Chưa bắt đầu | O16: 0
... A49: H08 | B49: Hoàn thiện | C49: Tài liệu | D49: Hoàn thiện báo cáo, hướng dẫn người dùng và kịch bản thuyết trình | E49: Người D | F49: Người A | G49: 8 | H49: 8 | I49: 8 | J49: P0 | K49: H03,H05,H06,H07 | L49: Report + user guide + demo script | M49: Tài liệu khớp sản phẩm; demo 10–15 phút chạy được | N49: Chưa bắt đầu | O49: 0

Sheet Timeline 8 tuần
A1: TIMELINE 8 TUẦN — BẢN ẨN DANH
A3: ID | B3: Task | C3: Owner | D3: Ưu tiên | E3: Giờ | F3: Tuần 1 | G3: Tuần 2 | H3: Tuần 3 | I3: Tuần 4 | J3: Tuần 5 | K3: Tuần 6 | L3: Tuần 7 | M3: Tuần 8
A4: P01 | B4: Chốt kiến trúc, module, luồng dữ liệu và ADR | C4: Người A | D4: P0 | E4: 6 | F4: ■
A5: P02 | B5: Chuẩn hoá endpoint và data contract; xử lý xung đột /notes/quick, /notes, /notes/ragged | C5: Người B | D5: P0 | E5: 8 | F5: ■
A6: P03 | B6: Spike lựa chọn AI Provider: Dify hay service riêng; đo khả năng chunk/embed/rerank | C6: Người C | D6: P0 | E6: 8 | F6: ■
A7: P04 | B7: Vẽ user flow và wireframe cho 5 chức năng trong kịch bản | C7: Người D | D7: P0 | E7: 8 | F7: ■
A8: P05 | B8: Khởi tạo TypeScript + Manifest V3, build/lint/test và cấu trúc module | C8: Người A | D8: P0 | E8: 8 | F8: ■ | G8: ■
A9: P06 | B9: Khởi tạo Python API, cấu hình môi trường, health check và test framework | C9: Người B | D9: P0 | E9: 8 | F9: ■ | G9: ■
A10: P07 | B10: Khởi tạo AI service/adapter cho local provider và mock provider | C10: Người C | D10: P0 | E10: 8 | F10: ■ | G10: ■
A11: P08 | B11: Lập test strategy, traceability matrix từ kịch bản và Definition of Done | C11: Người D | D11: P0 | E11: 6 | F11: ■ | G11: ■
A12: A01 | B12: Thiết kế schema user/note/chunk/category/quota và migration | C12: Người B | D12: P0 | E12: 8 | G12: ■
A13: A02 | B13: Xây dựng đăng ký/đăng nhập, hash mật khẩu và token/session | C13: Người B | D13: P0 | E13: 10 | G13: ■ | H13: ■
A14: A03 | B14: Tích hợp đăng nhập và lưu token an toàn trong extension | C14: Người A | D14: P0 | E14: 8 | G14: ■ | H14: ■
A15: A04 | B15: Xây dựng quota middleware và nhật ký tiêu hao AI | C15: Người B | D15: P0 | E15: 8 | H15: ■
A16: A05 | B16: Xây design system và app shell: loading/empty/error/toast/modal | C16: Người D | D16: P0 | E16: 8 | G16: ■ | H16: ■
A17: N01 | B17: Bắt selection, context menu và phím Ctrl-Alt-N | C17: Người A | D17: P0 | E17: 8 | H17: ■
A18: N02 | B18: Popup snippet, đếm ngược 5 giây và hoàn tác Ctrl-Alt-Z | C18: Người D | D18: P0 | E18: 8 | H18: ■ | I18: ■
A19: N03 | B19: Cài API tạo note nhanh, xác thực ownership và lưu PostgreSQL | C19: Người B | D19: P0 | E19: 10 | H19: ■ | I19: ■
A20: N04 | B20: Cài semantic chunking + embedding, định danh chunk UUID | C20: Người C | D20: P0 | E20: 10 | H20: ■ | I20: ■
A21: N05 | B21: Lưu vector pgvector và cập nhật quota sau xử lý | C21: Người C | D21: P0 | E21: 8 | I21: ■
A22: N06 | B22: Local state cho hàng chờ, retry và trạng thái note | C22: Người A | D22: P0 | E22: 8 | I22: ■
A23: N07 | B23: Kiểm thử E2E ghi chú nhanh, undo, hết quota và mất mạng | C23: Người D | D23: P0 | E23: 6 | I23: ■
A24: C01 | B24: API GET/PUT/DELETE note, filter metadata/category và bulk delete | C24: Người B | D24: P0 | E24: 10 | I24: ■ | J24: ■
A25: C02 | B25: IndexedDB cache/offline storage và chiến lược sync | C25: Người A | D25: P0 | E25: 10 | I25: ■ | J25: ■
A26: C03 | B26: Màn hình danh sách/chi tiết/sửa/xoá note và phân mục | C26: Người D | D26: P0 | E26: 10 | I26: ■ | J26: ■
A27: C04 | B27: Tích hợp metadata, category filter và đồng bộ trạng thái UI | C27: Người A | D27: P0 | E27: 6 | J27: ■
A28: C05 | B28: Test CRUD, cache-first, offline, sync conflict và xoá hàng loạt | C28: Người D | D28: P0 | E28: 6 | J28: ■
A29: R01 | B29: Xây hybrid retrieval: BM25 + cosine similarity + search pool theo user | C29: Người C | D29: P0 | E29: 12 | I29: ■ | J29: ■
A30: R02 | B30: Tích hợp rerank top-k và fallback khi provider lỗi | C30: Người C | D30: P0 | E30: 8 | J30: ■
A31: R03 | B31: Cài POST /search/ranking: auth, quota, metadata filter và response | C31: Người B | D31: P0 | E31: 10 | J31: ■ | K31: ■
A32: R04 | B32: Màn hình tìm kiếm/chat, gọi API và render chunk/rank | C32: Người A | D32: P0 | E32: 8 | J32: ■ | K32: ■
A33: R05 | B33: Đánh giá trải nghiệm kết quả RAG và test phân quyền/quota | C33: Người D | D33: P0 | E33: 6 | K33: ■
A34: S01 | B34: Readability extraction, session UUID theo tab+user | C34: Người A | D34: P1 | E34: 8 | K34: ■
A35: S02 | B35: Cài /skim/prepare, /skim/search và bộ nhớ session có TTL | C35: Người C | D35: P1 | E35: 10 | K35: ■ | L35: ■
A36: S03 | B36: Pipeline chunk/embed/search/rerank tạm thời cho nội dung trang | C36: Người C | D36: P1 | E36: 10 | K36: ■ | L36: ■
A37: S04 | B37: UI prompt, hint chuẩn bị/tìm kiếm, preview và chọn đoạn để lưu | C37: Người D | D37: P1 | E37: 8 | K37: ■ | L37: ■
A38: S05 | B38: Cài lưu các chunk đã chọn qua contract note thống nhất | C38: Người B | D38: P1 | E38: 6 | L38: ■
A39: S06 | B39: E2E skim: trang dài, chưa ready, hết quota, session hết hạn | C39: Người D | D39: P1 | E39: 6 | L39: ■
A40: G01 | B40: Đặc tả riêng chức năng Tóm tắt nội dung đang thiếu trong file kịch bản | C40: Người D | D40: P1 | E40: 5 | G40: ■
A41: G02 | B41: Chốt lịch trình cá nhân, dữ liệu profile và cơ chế consent | C41: Người A | D41: P2 | E41: 4 | G41: ■
...

Sheet Tải công việc
A1: TẢI CÔNG VIỆC THEO THÀNH VIÊN — BẢN ẨN DANH
A3: Thành viên | B3: Vai trò | C3: Số task | D3: Tổng giờ | E3: T1 | F3: T2 | G3: T3 | H3: T4 | I3: T5 | J3: T6 | K3: T7 | L3: T8
A4: Người A | B4: Tech Lead / Browser Extension | C4: =COUNTIF('Backlog phân công'!$E$4:$E$49,A4) | D4: =SUMIF('Backlog phân công'!$E$4:$E$49,A4,'Backlog phân công'!$I$4:$I$49) | E4: =SUMPRODUCT(('Backlog phân công'!$E$4:$E$49=$A4)*('Backlog phân công'!$G$4:$G$49<=1)*('Backlog phân công'!$H$4:$H$49>=1)*('Backlog phân công'!$I$4:$I$49/('Backlog phân công'!$H$4:$H$49-'Backlog phân công'!$G$4:$G$49+1))) | F4: =SUMPRODUCT(('Backlog phân công'!$E$4:$E$49=$A4)*('Backlog phân công'!$G$4:$G$49<=2)*('Backlog phân công'!$H$4:$H$49>=2)*('Backlog phân công'!$I$4:$I$49/('Backlog phân công'!$H$4:$H$49-'Backlog phân công'!$G$4:$G$49+1))) | G4: =SUMPRODUCT(('Backlog phân công'!$E$4:$E$49=$A4)*('Backlog phân công'!$G$4:$G$49<=3)*('Backlog phân công'!$H$4:$H$49>=3)*('Backlog phân công'!$I$4:$I$49/('Backlog phân công'!$H$4:$H$49-'Backlog phân công'!$G$4:$G$49+1))) | H4: =SUMPRODUCT(('Backlog phân công'!$E$4:$E$49=$A4)*('Backlog phân công'!$G$4:$G$49<=4)*('Backlog phân công'!$H$4:$H$49>=4)*('Backlog phân công'!$I$4:$I$49/('Backlog phân công'!$H$4:$H$49-'Backlog phân công'!$G$4:$G$49+1))) | I4: =SUMPRODUCT(('Backlog phân công'!$E$4:$E$49=$A4)*('Backlog phân công'!$G$4:$G$49<=5)*('Backlog phân công'!$H$4:$H$49>=5)*('Backlog phân công'!$I$4:$I$49/('Backlog phân công'!$H$4:$H$49-'Backlog phân công'!$G$4:$G$49+1))) | J4: =SUMPRODUCT(('Backlog phân công'!$E$4:$E$49=$A4)*('Backlog phân công'!$G$4:$G$49<=6)*('Backlog phân công'!$H$4:$H$49>=6)*('Backlog phân công'!$I$4:$I$49/('Backlog phân công'!$H$4:$H$49-'Backlog phân công'!$G$4:$G$49+1))) | K4: =SUMPRODUCT(('Backlog phân công'!$E$4:$E$49=$A4)*('Backlog phân công'!$G$4:$G$49<=7)*('Backlog phân công'!$H$4:$H$49>=7)*('Backlog phân công'!$I$4:$I$49/('Backlog phân công'!$H$4:$H$49-'Backlog phân công'!$G$4:$G$49+1))) | L4: =SUMPRODUCT(('Backlog phân công'!$E$4:$E$49=$A4)*('Backlog phân công'!$G$4:$G$49<=8)*('Backlog phân công'!$H$4:$H$49>=8)*('Backlog phân công'!$I$4:$I$49/('Backlog phân công'!$H$4:$H$49-'Backlog phân công'!$G$4:$G$49+1)))
A5: Người B | B5: Backend Lead | C5: =COUNTIF('Backlog phân công'!$E$4:$E$49,A5) | D5: =SUMIF('Backlog phân công'!$E$4:$E$49,A5,'Backlog phân công'!$I$4:$I$49) | E5: =SUMPRODUCT(('Backlog phân công'!$E$4:$E$49=$A5)*('Backlog phân công'!$G$4:$G$49<=1)*('Backlog phân công'!$H$4:$H$49>=1)*('Backlog phân công'!$I$4:$I$49/('Backlog phân công'!$H$4:$H$49-'Backlog phân công'!$G$4:$G$49+1))) | F5: =SUMPRODUCT(('Backlog phân công'!$E$4:$E$49=$A5)*('Backlog phân công'!$G$4:$G$49<=2)*('Backlog phân công'!$H$4:$H$49>=2)*('Backlog phân công'!$I$4:$I$49/('Backlog phân công'!$H$4:$H$49-'Backlog phân công'!$G$4:$G$49+1))) | G5: =SUMPRODUCT(('Backlog phân công'!$E$4:$E$49=$A5)*('Backlog phân công'!$G$4:$G$49<=3)*('Backlog phân công'!$H$4:$H$49>=3)*('Backlog phân công'!$I$4:$I$49/('Backlog phân công'!$H$4:$H$49-'Backlog phân công'!$G$4:$G$49+1))) | H5: =SUMPRODUCT(('Backlog phân công'!$E$4:$E$49=$A5)*('Backlog phân công'!$G$4:$G$49<=4)*('Backlog phân công'!$H$4:$H$49>=4)*('Backlog phân công'!$I$4:$I$49/('Backlog phân công'!$H$4:$H$49-'Backlog phân công'!$G$4:$G$49+1))) | I5: =SUMPRODUCT(('Backlog phân công'!$E$4:$E$49=$A5)*('Backlog phân công'!$G$4:$G$49<=5)*('Backlog phân công'!$H$4:$H$49>=5)*('Backlog phân công'!$I$4:$I$49/('Backlog phân công'!$H$4:$H$49-'Backlog phân công'!$G$4:$G$49+1))) | J5: =SUMPRODUCT(('Backlog phân công'!$E$4:$E$49=$A5)*('Backlog phân công'!$G$4:$G$49<=6)*('Backlog phân công'!$H$4:$H$49>=6)*('Backlog phân công'!$I$4:$I$49/('Backlog phân công'!$H$4:$H$49-'Backlog phân công'!$G$4:$G$49+1))) | K5: =SUMPRODUCT(('Backlog phân công'!$E$4:$E$49=$A5)*('Backlog phân công'!$G$4:$G$49<=7)*('Backlog phân công'!$H$4:$H$49>=7)*('Backlog phân công'!$I$4:$I$49/('Backlog phân công'!$H$4:$H$49-'Backlog phân công'!$G$4:$G$49+1))) | L5: =SUMPRODUCT(('Backlog phân công'!$E$4:$E$49=$A5)*('Backlog phân công'!$G$4:$G$49<=8)*('Backlog phân công'!$H$4:$H$49>=8)*('Backlog phân công'!$I$4:$I$49/('Backlog phân công'!$H$4:$H$49-'Backlog phân công'!$G$4:$G$49+1)))
A6: Người C | B6: AI/RAG Lead | C6: =COUNTIF('Backlog phân công'!$E$4:$E$49,A6) | D6: =SUMIF('Backlog phân công'!$E$4:$E$49,A6,'Backlog phân công'!$I$4:$I$49) | E6: =SUMPRODUCT(('Backlog phân công'!$E$4:$E$49=$A6)*('Backlog phân công'!$G$4:$G$49<=1)*('Backlog phân công'!$H$4:$H$49>=1)*('Backlog phân công'!$I$4:$I$49/('Backlog phân công'!$H$4:$H$49-'Backlog phân công'!$G$4:$G$49+1))) | F6: =SUMPRODUCT(('Backlog phân công'!$E$4:$E$49=$A6)*('Backlog phân công'!$G$4:$G$49<=2)*('Backlog phân công'!$H$4:$H$49>=2)*('Backlog phân công'!$I$4:$I$49/('Backlog phân công'!$H$4:$H$49-'Backlog phân công'!$G$4:$G$49+1))) | G6: =SUMPRODUCT(('Backlog phân công'!$E$4:$E$49=$A6)*('Backlog phân công'!$G$4:$G$49<=3)*('Backlog phân công'!$H$4:$H$49>=3)*('Backlog phân công'!$I$4:$I$49/('Backlog phân công'!$H$4:$H$49-'Backlog phân công'!$G$4:$G$49+1))) | H6: =SUMPRODUCT(('Backlog phân công'!$E$4:$E$49=$A6)*('Backlog phân công'!$G$4:$G$49<=4)*('Backlog phân công'!$H$4:$H$49>=4)*('Backlog phân công'!$I$4:$I$49/('Backlog phân công'!$H$4:$H$49-'Backlog phân công'!$G$4:$G$49+1))) | I6: =SUMPRODUCT(('Backlog phân công'!$E$4:$E$49=$A6)*('Backlog phân công'!$G$4:$G$49<=5)*('Backlog phân công'!$H$4:$H$49>=5)*('Backlog phân công'!$I$4:$I$49/('Backlog phân công'!$H$4:$H$49-'Backlog phân công'!$G$4:$G$49+1))) | J6: =SUMPRODUCT(('Backlog phân công'!$E$4:$E$49=$A6)*('Backlog phân công'!$G$4:$G$49<=6)*('Backlog phân công'!$H$4:$H$49>=6)*('Backlog phân công'!$I$4:$I$49/('Backlog phân công'!$H$4:$H$49-'Backlog phân công'!$G$4:$G$49+1))) | K6: =SUMPRODUCT(('Backlog phân công'!$E$4:$E$49=$A6)*('Backlog phân công'!$G$4:$G$49<=7)*('Backlog phân công'!$H$4:$H$49>=7)*('Backlog phân công'!$I$4:$I$49/('Backlog phân công'!$H$4:$H$49-'Backlog phân công'!$G$4:$G$49+1))) | L6: =SUMPRODUCT(('Backlog phân công'!$E$4:$E$49=$A6)*('Backlog phân công'!$G$4:$G$49<=8)*('Backlog phân công'!$H$4:$H$49>=8)*('Backlog phân công'!$I$4:$I$49/('Backlog phân công'!$H$4:$H$49-'Backlog phân công'!$G$4:$G$49+1)))
A7: Người D | B7: UI/UX & QA Lead | C7: =COUNTIF('Backlog phân công'!$E$4:$E$49,A7) | D7: =SUMIF('Backlog phân công'!$E$4:$E$49,A7,'Backlog phân công'!$I$4:$I$49) | E7: =SUMPRODUCT(('Backlog phân công'!$E$4:$E$49=$A7)*('Backlog phân công'!$G$4:$G$49<=1)*('Backlog phân công'!$H$4:$H$49>=1)*('Backlog phân công'!$I$4:$I$49/('Backlog phân công'!$H$4:$H$49-'Backlog phân công'!$G$4:$G$49+1))) | F7: =SUMPRODUCT(('Backlog phân công'!$E$4:$E$49=$A7)*('Backlog phân công'!$G$4:$G$49<=2)*('Backlog phân công'!$H$4:$H$49>=2)*('Backlog phân công'!$I$4:$I$49/('Backlog phân công'!$H$4:$H$49-'Backlog phân công'!$G$4:$G$49+1))) | G7: =SUMPRODUCT(('Backlog phân công'!$E$4:$E$49=$A7)*('Backlog phân công'!$G$4:$G$49<=3)*('Backlog phân công'!$H$4:$H$49>=3)*('Backlog phân công'!$I$4:$I$49/('Backlog phân công'!$H$4:$H$49-'Backlog phân công'!$G$4:$G$49+1))) | H7: =SUMPRODUCT(('Backlog phân công'!$E$4:$E$49=$A7)*('Backlog phân công'!$G$4:$G$49<=4)*('Backlog phân công'!$H$4:$H$49>=4)*('Backlog phân công'!$I$4:$I$49/('Backlog phân công'!$H$4:$H$49-'Backlog phân công'!$G$4:$G$49+1))) | I7: =SUMPRODUCT(('Backlog phân công'!$E$4:$E$49=$A7)*('Backlog phân công'!$G$4:$G$49<=5)*('Backlog phân công'!$H$4:$H$49>=5)*('Backlog phân công'!$I$4:$I$49/('Backlog phân công'!$H$4:$H$49-'Backlog phân công'!$G$4:$G$49+1))) | J7: =SUMPRODUCT(('Backlog phân công'!$E$4:$E$49=$A7)*('Backlog phân công'!$G$4:$G$49<=6)*('Backlog phân công'!$H$4:$H$49>=6)*('Backlog phân công'!$I$4:$I$49/('Backlog phân công'!$H$4:$H$49-'Backlog phân công'!$G$4:$G$49+1))) | K7: =SUMPRODUCT(('Backlog phân công'!$E$4:$E$49=$A7)*('Backlog phân công'!$G$4:$G$49<=7)*('Backlog phân công'!$H$4:$H$49>=7)*('Backlog phân công'!$I$4:$I$49/('Backlog phân công'!$H$4:$H$49-'Backlog phân công'!$G$4:$G$49+1))) | L7: =SUMPRODUCT(('Backlog phân công'!$E$4:$E$49=$A7)*('Backlog phân công'!$G$4:$G$49<=8)*('Backlog phân công'!$H$4:$H$49>=8)*('Backlog phân công'!$I$4:$I$49/('Backlog phân công'!$H$4:$H$49-'Backlog phân công'!$G$4:$G$49+1)))
A10: Cách đọc | B10: T1–T8 phân bổ giờ ước tính đều theo số tuần của task. Dùng để nhận biết chênh lệch tải; không phải timesheet thực tế.

Sheet Rủi ro & quyết định
A1: RỦI RO, KHOẢNG TRỐNG & HƯỚNG XỬ LÝ — BẢN ẨN DANH
A3: ID | B3: Rủi ro / khoảng trống | C3: Ảnh hưởng | D3: Khả năng | E3: Giảm thiểu / quyết định | F3: Owner
A4: R-01 | B4: Tóm tắt nội dung có trong Word nhưng chưa có kịch bản chi tiết | C4: Cao | D4: Cao | E4: Đặc tả ở G01; chỉ đưa vào MVP sau khi chốt acceptance/quota | F4: Người D
A5: R-02 | B5: Tên endpoint ghi chú không thống nhất giữa các bước | C5: Cao | D5: Trung bình | E5: Chuẩn hoá OpenAPI ở P02 trước khi code client/server | F5: Người B
A6: R-03 | B6: Header chỉ ghi 'định danh user', chưa định nghĩa cơ chế auth | C6: Cao | D6: Cao | E6: Dùng token/session chuẩn, ownership check mọi truy vấn | F6: Người B
A7: R-04 | B7: Quota và silent skip AI có thể gây trạng thái note khó hiểu | C7: Trung bình | D7: Cao | E7: Tách trạng thái saved/processed; log lý do và hiển thị phù hợp | F7: Người A
A8: R-05 | B8: Dữ liệu web cá nhân được gửi đến AI provider | C8: Cao | D8: Trung bình | E8: Consent, tối thiểu hoá dữ liệu, retention policy và tùy chọn local | F8: Người A
A9: R-06 | B9: Hybrid search/rerank có độ trễ cao | C9: Trung bình | D9: Cao | E9: Benchmark sớm, timeout, cache và fallback không rerank | F9: Người C
A10: R-07 | B10: IndexedDB và server có thể xung đột dữ liệu | C10: Trung bình | D10: Cao | E10: Chốt version/updatedAt và quy tắc conflict trong C02 | F10: Người A
A11: R-08 | B11: Readability không ổn định trên SPA/trang đặc biệt | C11: Trung bình | D11: Trung bình | E11: Bộ trang thử chuẩn, fallback selection/body text và thông báo giới hạn | F11: Người A
A12: R-09 | B12: Self-host LLM vượt tài nguyên máy demo | C12: Cao | D12: Trung bình | E12: Provider adapter, model nhẹ, mock/demo fallback | F12: Người C
A13: R-10 | B13: Phạm vi rộng so với nhóm 4 người | C13: Cao | D13: Cao | E13: Khoá P0; Skim là P1; lịch trình cá nhân là P2 | F13: Người A

Sheet Kế hoạch tuần
A1: MỤC TIÊU, MỐC BÀN GIAO & NHỊP LÀM VIỆC — BẢN ẨN DANH
A3: Tuần | B3: Mục tiêu | C3: Mốc bàn giao | D3: Điều kiện qua cổng | E3: Review chính | F3: Ghi chú
A4: 1 | B4: Chốt kiến trúc, API, AI và UX | C4: ADR, OpenAPI draft, wireframe, repo skeleton | D4: Nhóm thống nhất scope P0/P1/P2 | E4: Người A + cả nhóm | F4: Không code lệch contract trước P02
A5: 2 | B5: Hoàn thiện nền tảng | C5: Schema, test plan, UI shell, đặc tả summary | D5: Skeleton chạy và migration pass | E5: Người B/Người D | F5: Chốt G01/G02
A6: 3 | B6: Auth/quota và ghi chú đầu-cuối | C6: Auth + selection + popup + API note | D6: Lưu được note không AI | E6: Người A/Người B | F6: Ưu tiên vertical slice
A7: 4 | B7: MVP ghi chú + vector | C7: Chunk/embed/vector + queue + E2E | D7: Luồng N01–N07 pass | E7: Người C/Người D | F7: Mốc MVP-1
A8: 5 | B8: Thư viện note + retrieval | C8: CRUD/cache/UI + hybrid/rerank | D8: Offline cơ bản và search backend pass | E8: Cả nhóm | F8: Không mở P1 nếu P0 đỏ
A9: 6 | B9: RAG hoàn chỉnh, bắt đầu skim | C9: Search UI/API + Readability + skim skeleton | D9: RAG P0 nghiệm thu | E9: Người C/Người A | F9: Mốc MVP-2
A10: 7 | B10: Skim và hardening | C10: Skim E2E + security + deploy/eval draft | D10: P1 pass hoặc cắt khỏi demo | E10: Người B/Người D | F10: Khoá tính năng cuối tuần
A11: 8 | B11: Release và thuyết trình | C11: Regression, release candidate, report, demo | D11: 0 lỗi P0/P1; demo rehearsal pass | E11: Cả nhóm | F11: Không thêm tính năng mới
A14: Nhịp cố định | B14: Đầu tuần: chốt mục tiêu & dependency (30’). Giữa tuần: sync blocker (15’). Cuối tuần: demo + review + cập nhật backlog (45’). Pull request cần 1 reviewer; thay đổi contract cần owner Backend + client liên quan duyệt.
